2024-10-29 15:43:14,823) | INFO | "test_walk1" выполнен успешно
2024-10-29 15:43:14,824) | ERROR | Ошибка-"test2_walk"
Traceback (most recent call last):
  File "D:\larchim\@pyton\module12\tests_12_4.py", line 35, in test2_walk
    r1 = runner.Runner("Ходок", -8)
         ^^^^^^^^^^^^^^^^^^^^^^^^^^
  File "D:\larchim\@pyton\module12\rt_with_exceptions.py", line 11, in __init__
    raise ValueError(f'Скорость не может быть отрицательной, сейчас {speed}')
ValueError: Скорость не может быть отрицательной, сейчас -8
2024-10-29 15:43:14,825) | INFO | "test_challenge" выполнен успешно
2024-10-29 15:43:14,825) | INFO | "test_run" выполнен успешно
2024-10-29 15:43:14,825) | ERROR | Ошибка - "test_walk"
Traceback (most recent call last):
  File "D:\larchim\@pyton\module12\tests_12_4.py", line 11, in test_walk
    r1 = runner.Runner(7, 4)
         ^^^^^^^^^^^^^^^^^^^
  File "D:\larchim\@pyton\module12\rt_with_exceptions.py", line 6, in __init__
    raise TypeError(f'Имя может быть только строкой, передано {type(name).__name__}')
TypeError: Имя может быть только строкой, передано int
